Workbook

Sheet Como usar
A1: Fichas Concierge Milano — planilha
A2: Legenda: cinza = já preenchido e verificado · amarelo = você preenche
A4: A PLANILHA E O APP
B5: As colunas desta planilha são exatamente as mesmas do app, na mesma ordem.
B6: No app: aba Exportar → Copiar tabela (CSV) → cole na aba Fichas a partir da célula A1.
B7: Use o app para preencher em campo. Use a planilha para guardar, filtrar e consultar no computador.
A9: O QUE MARCAR
B10: Quase tudo é lista suspensa. Três colunas aceitam vários valores separados por ponto e vírgula:
B11: Serve para · Faixa etária · Ocasião · Não indicar para · Pontos fracos.
B12: No app isso é um toque por opção. Aqui, escreva igual ao vocabulário (a consulta procura o texto).
A14: VOCABULÁRIO (escreva exatamente assim)
A15: Serve para | B15: Casal · Família com crianças · Solo · Grupo · Negócios
A16: Faixa etária | B16: 18–30 · 30–50 · 50+ · Indiferente
A17: Ocasião | B17: Romântico · Celebração · Business · Cultural · Sem turistas · Instagram · Relax · Noite
A18: Pontos fracos | B18: Fila · Barulhento · Reserva difícil · Caro para o que entrega · Turístico demais ·
B19: Serviço lento · Sem opção vegetariana · Escada sem elevador · Fecha cedo · Mesa apertada
A21: A CONSULTA
B22: Pontos: ocasião +3 · serve para +3 · chuva +3 · faixa etária +2 · preço +2 · categoria +2 ·
B23: bairro +2 · sua nota +1 a +5. Elimina quem fecha no dia, quem está em 'Não indicar para',
B24: e — se você exigir — quem não estiver marcado como LGBTQIA+ friendly.
B25: Ela fica útil a partir de umas 30 fichas preenchidas.
A27: REGRA QUE NÃO MUDA
B28: Horários e telefones mudam. Antes de mandar um hóspede, confirme no dia.
B29: E não preencha ficha de lugar onde você não foi.
A31: Exemplo de linha preenchida
A32: Nota | B32: 4
A33: Faixa | B33: €€
A34: Serve para | B34: Casal; Solo
A35: Faixa etária | B35: 30–50; 50+
A36: Ocasião | B36: Cultural; Romântico
A37: Ruído | B37: Silencioso
A38: Chuva | B38: Sim
A39: LGBTQIA+ friendly | B39: Sim
A40: Ponto forte | B40: Sala do Mantegna vazia às 9h; Hayez no fim do percurso
A41: Plano B | B41: Ambrosiana, 8 min a pé

Sheet Consulta
A1: Consulta A / B / C
A2: Preencha os campos amarelos. As três opções aparecem abaixo.
A3: Composição do grupo | B3: Qualquer
A4: Ocasião | B4: Qualquer
A5: Dia da semana | B5: Qualquer
A6: Faixa de preço | B6: Qualquer
A7: Está chovendo | B7: Não
A8: Categoria | B8: Qualquer
A9: Bairro | B9: Qualquer
A10: Precisa ser LGBTQIA+ friendly | B10: Não
A11: Só lugares que já visitei | B11: Não
A12: Faixa etária | B12: Qualquer
A14: RESULTADO
B15: Lugar | C15: Bairro | D15: Categoria | E15: Faixa | F15: Fecha | G15: Transporte | H15: Ponto forte | I15: Plano B | J15: Nota
A16: A — principal | B16: =IFERROR(IF(LARGE(Fichas!$AF$2:$AF$260,1)<=0,"—",IF(INDEX(Fichas!$B$2:$B$260,MATCH(LARGE(Fichas!$AF$2:$AF$260,1),Fichas!$AF$2:$AF$260,0))=0,"—",INDEX(Fichas!$B$2:$B$260,MATCH(LARGE(Fichas!$AF$2:$AF$260,1),Fichas!$AF$2:$AF$260,0)))),"—") -> Duomo di Milano — Catedral | C16: =IFERROR(IF(LARGE(Fichas!$AF$2:$AF$260,1)<=0,"—",IF(INDEX(Fichas!$D$2:$D$260,MATCH(LARGE(Fichas!$AF$2:$AF$260,1),Fichas!$AF$2:$AF$260,0))=0,"—",INDEX(Fichas!$D$2:$D$260,MATCH(LARGE(Fichas!$AF$2:$AF$260,1),Fichas!$AF$2:$AF$260,0)))),"—") -> Duomo | D16: =IFERROR(IF(LARGE(Fichas!$AF$2:$AF$260,1)<=0,"—",IF(INDEX(Fichas!$C$2:$C$260,MATCH(LARGE(Fichas!$AF$2:$AF$260,1),Fichas!$AF$2:$AF$260,0))=0,"—",INDEX(Fichas!$C$2:$C$260,MATCH(LARGE(Fichas!$AF$2:$AF$260,1),Fichas!$AF$2:$AF$260,0)))),"—") -> Monumento | E16: =IFERROR(IF(LARGE(Fichas!$AF$2:$AF$260,1)<=0,"—",IF(INDEX(Fichas!$O$2:$O$260,MATCH(LARGE(Fichas!$AF$2:$AF$260,1),Fichas!$AF$2:$AF$260,0))=0,"—",INDEX(Fichas!$O$2:$O$260,MATCH(LARGE(Fichas!$AF$2:$AF$260,1),Fichas!$AF$2:$AF$260,0)))),"—") -> — | F16: =IFERROR(IF(LARGE(Fichas!$AF$2:$AF$260,1)<=0,"—",IF(INDEX(Fichas!$H$2:$H$260,MATCH(LARGE(Fichas!$AF$2:$AF$260,1),Fichas!$AF$2:$AF$260,0))=0,"—",INDEX(Fichas!$H$2:$H$260,MATCH(LARGE(Fichas!$AF$2:$AF$260,1),Fichas!$AF$2:$AF$260,0)))),"—") -> Nunca | G16: =IFERROR(IF(LARGE(Fichas!$AF$2:$AF$260,1)<=0,"—",IF(INDEX(Fichas!$K$2:$K$260,MATCH(LARGE(Fichas!$AF$2:$AF$260,1),Fichas!$AF$2:$AF$260,0))=0,"—",INDEX(Fichas!$K$2:$K$260,MATCH(LARGE(Fichas!$AF$2:$AF$260,1),Fichas!$AF$2:$AF$260,0)))),"—") -> M1/M3 Duomo | H16: =IFERROR(IF(LARGE(Fichas!$AF$2:$AF$260,1)<=0,"—",IF(INDEX(Fichas!$AD$2:$AD$260,MATCH(LARGE(Fichas!$AF$2:$AF$260,1),Fichas!$AF$2:$AF$260,0))=0,"—",INDEX(Fichas!$AD$2:$AD$260,MATCH(LARGE(Fichas!$AF$2:$AF$260,1),Fichas!$AF$2:$AF$260,0)))),"—") -> — | I16: =IFERROR(IF(LARGE(Fichas!$AF$2:$AF$260,1)<=0,"—",IF(INDEX(Fichas!$AE$2:$AE$260,MATCH(LARGE(Fichas!$AF$2:$AF$260,1),Fichas!$AF$2:$AF$260,0))=0,"—",INDEX(Fichas!$AE$2:$AE$260,MATCH(LARGE(Fichas!$AF$2:$AF$260,1),Fichas!$AF$2:$AF$260,0)))),"—") -> — | J16: =IFERROR(IF(LARGE(Fichas!$AF$2:$AF$260,1)<=0,"—",IF(INDEX(Fichas!$N$2:$N$260,MATCH(LARGE(Fichas!$AF$2:$AF$260,1),Fichas!$AF$2:$AF$260,0))=0,"—",INDEX(Fichas!$N$2:$N$260,MATCH(LARGE(Fichas!$AF$2:$AF$260,1),Fichas!$AF$2:$AF$260,0)))),"—") -> —
A17: B — equivalente | B17: =IFERROR(IF(LARGE(Fichas!$AF$2:$AF$260,2)<=0,"—",IF(INDEX(Fichas!$B$2:$B$260,MATCH(LARGE(Fichas!$AF$2:$AF$260,2),Fichas!$AF$2:$AF$260,0))=0,"—",INDEX(Fichas!$B$2:$B$260,MATCH(LARGE(Fichas!$AF$2:$AF$260,2),Fichas!$AF$2:$AF$260,0)))),"—") -> Duomo — Terrazze (terraços) | C17: =IFERROR(IF(LARGE(Fichas!$AF$2:$AF$260,2)<=0,"—",IF(INDEX(Fichas!$D$2:$D$260,MATCH(LARGE(Fichas!$AF$2:$AF$260,2),Fichas!$AF$2:$AF$260,0))=0,"—",INDEX(Fichas!$D$2:$D$260,MATCH(LARGE(Fichas!$AF$2:$AF$260,2),Fichas!$AF$2:$AF$260,0)))),"—") -> Duomo | D17: =IFERROR(IF(LARGE(Fichas!$AF$2:$AF$260,2)<=0,"—",IF(INDEX(Fichas!$C$2:$C$260,MATCH(LARGE(Fichas!$AF$2:$AF$260,2),Fichas!$AF$2:$AF$260,0))=0,"—",INDEX(Fichas!$C$2:$C$260,MATCH(LARGE(Fichas!$AF$2:$AF$260,2),Fichas!$AF$2:$AF$260,0)))),"—") -> Monumento | E17: =IFERROR(IF(LARGE(Fichas!$AF$2:$AF$260,2)<=0,"—",IF(INDEX(Fichas!$O$2:$O$260,MATCH(LARGE(Fichas!$AF$2:$AF$260,2),Fichas!$AF$2:$AF$260,0))=0,"—",INDEX(Fichas!$O$2:$O$260,MATCH(LARGE(Fichas!$AF$2:$AF$260,2),Fichas!$AF$2:$AF$260,0)))),"—") -> — | F17: =IFERROR(IF(LARGE(Fichas!$AF$2:$AF$260,2)<=0,"—",IF(INDEX(Fichas!$H$2:$H$260,MATCH(LARGE(Fichas!$AF$2:$AF$260,2),Fichas!$AF$2:$AF$260,0))=0,"—",INDEX(Fichas!$H$2:$H$260,MATCH(LARGE(Fichas!$AF$2:$AF$260,2),Fichas!$AF$2:$AF$260,0)))),"—") -> Nunca | G17: =IFERROR(IF(LARGE(Fichas!$AF$2:$AF$260,2)<=0,"—",IF(INDEX(Fichas!$K$2:$K$260,MATCH(LARGE(Fichas!$AF$2:$AF$260,2),Fichas!$AF$2:$AF$260,0))=0,"—",INDEX(Fichas!$K$2:$K$260,MATCH(LARGE(Fichas!$AF$2:$AF$260,2),Fichas!$AF$2:$AF$260,0)))),"—") -> M1/M3 Duomo | H17: =IFERROR(IF(LARGE(Fichas!$AF$2:$AF$260,2)<=0,"—",IF(INDEX(Fichas!$AD$2:$AD$260,MATCH(LARGE(Fichas!$AF$2:$AF$260,2),Fichas!$AF$2:$AF$260,0))=0,"—",INDEX(Fichas!$AD$2:$AD$260,MATCH(LARGE(Fichas!$AF$2:$AF$260,2),Fichas!$AF$2:$AF$260,0)))),"—") -> — | I17: =IFERROR(IF(LARGE(Fichas!$AF$2:$AF$260,2)<=0,"—",IF(INDEX(Fichas!$AE$2:$AE$260,MATCH(LARGE(Fichas!$AF$2:$AF$260,2),Fichas!$AF$2:$AF$260,0))=0,"—",INDEX(Fichas!$AE$2:$AE$260,MATCH(LARGE(Fichas!$AF$2:$AF$260,2),Fichas!$AF$2:$AF$260,0)))),"—") -> — | J17: =IFERROR(IF(LARGE(Fichas!$AF$2:$AF$260,2)<=0,"—",IF(INDEX(Fichas!$N$2:$N$260,MATCH(LARGE(Fichas!$AF$2:$AF$260,2),Fichas!$AF$2:$AF$260,0))=0,"—",INDEX(Fichas!$N$2:$N$260,MATCH(LARGE(Fichas!$AF$2:$AF$260,2),Fichas!$AF$2:$AF$260,0)))),"—") -> —
A18: C — alternativa | B18: =IFERROR(IF(LARGE(Fichas!$AF$2:$AF$260,3)<=0,"—",IF(INDEX(Fichas!$B$2:$B$260,MATCH(LARGE(Fichas!$AF$2:$AF$260,3),Fichas!$AF$2:$AF$260,0))=0,"—",INDEX(Fichas!$B$2:$B$260,MATCH(LARGE(Fichas!$AF$2:$AF$260,3),Fichas!$AF$2:$AF$260,0)))),"—") -> Museo del Duomo | C18: =IFERROR(IF(LARGE(Fichas!$AF$2:$AF$260,3)<=0,"—",IF(INDEX(Fichas!$D$2:$D$260,MATCH(LARGE(Fichas!$AF$2:$AF$260,3),Fichas!$AF$2:$AF$260,0))=0,"—",INDEX(Fichas!$D$2:$D$260,MATCH(LARGE(Fichas!$AF$2:$AF$260,3),Fichas!$AF$2:$AF$260,0)))),"—") -> Duomo | D18: =IFERROR(IF(LARGE(Fichas!$AF$2:$AF$260,3)<=0,"—",IF(INDEX(Fichas!$C$2:$C$260,MATCH(LARGE(Fichas!$AF$2:$AF$260,3),Fichas!$AF$2:$AF$260,0))=0,"—",INDEX(Fichas!$C$2:$C$260,MATCH(LARGE(Fichas!$AF$2:$AF$260,3),Fichas!$AF$2:$AF$260,0)))),"—") -> Museu | E18: =IFERROR(IF(LARGE(Fichas!$AF$2:$AF$260,3)<=0,"—",IF(INDEX(Fichas!$O$2:$O$260,MATCH(LARGE(Fichas!$AF$2:$AF$260,3),Fichas!$AF$2:$AF$260,0))=0,"—",INDEX(Fichas!$O$2:$O$260,MATCH(LARGE(Fichas!$AF$2:$AF$260,3),Fichas!$AF$2:$AF$260,0)))),"—") -> — | F18: =IFERROR(IF(LARGE(Fichas!$AF$2:$AF$260,3)<=0,"—",IF(INDEX(Fichas!$H$2:$H$260,MATCH(LARGE(Fichas!$AF$2:$AF$260,3),Fichas!$AF$2:$AF$260,0))=0,"—",INDEX(Fichas!$H$2:$H$260,MATCH(LARGE(Fichas!$AF$2:$AF$260,3),Fichas!$AF$2:$AF$260,0)))),"—") -> Quarta | G18: =IFERROR(IF(LARGE(Fichas!$AF$2:$AF$260,3)<=0,"—",IF(INDEX(Fichas!$K$2:$K$260,MATCH(LARGE(Fichas!$AF$2:$AF$260,3),Fichas!$AF$2:$AF$260,0))=0,"—",INDEX(Fichas!$K$2:$K$260,MATCH(LARGE(Fichas!$AF$2:$AF$260,3),Fichas!$AF$2:$AF$260,0)))),"—") -> M1/M3 Duomo | H18: =IFERROR(IF(LARGE(Fichas!$AF$2:$AF$260,3)<=0,"—",IF(INDEX(Fichas!$AD$2:$AD$260,MATCH(LARGE(Fichas!$AF$2:$AF$260,3),Fichas!$AF$2:$AF$260,0))=0,"—",INDEX(Fichas!$AD$2:$AD$260,MATCH(LARGE(Fichas!$AF$2:$AF$260,3),Fichas!$AF$2:$AF$260,0)))),"—") -> — | I18: =IFERROR(IF(LARGE(Fichas!$AF$2:$AF$260,3)<=0,"—",IF(INDEX(Fichas!$AE$2:$AE$260,MATCH(LARGE(Fichas!$AF$2:$AF$260,3),Fichas!$AF$2:$AF$260,0))=0,"—",INDEX(Fichas!$AE$2:$AE$260,MATCH(LARGE(Fichas!$AF$2:$AF$260,3),Fichas!$AF$2:$AF$260,0)))),"—") -> — | J18: =IFERROR(IF(LARGE(Fichas!$AF$2:$AF$260,3)<=0,"—",IF(INDEX(Fichas!$N$2:$N$260,MATCH(LARGE(Fichas!$AF$2:$AF$260,3),Fichas!$AF$2:$AF$260,0))=0,"—",INDEX(Fichas!$N$2:$N$260,MATCH(LARGE(Fichas!$AF$2:$AF$260,3),Fichas!$AF$2:$AF$260,0)))),"—") -> —
A20: Se aparecer '—', não há ficha preenchida que atenda. Alargue os critérios ou preencha mais fichas.

Sheet Listas
A1: cat | B1: bairro | C1: fecha | D1: reserva | E1: simnao | F1: tri | G1: nota | H1: faixa | I1: ruido | J1: grupo | K1: espera | L1: ateTarde | M1: dias | N1: composicao | O1: idade | P1: ocasiao | Q1: qComposicao | R1: qIdade | S1: qOcasiao | T1: qFaixa | U1: qCat | V1: qBairro | W1: qDia
A2: Museu | B2: 5Vie | C2: Segunda | D2: Não precisa | E2: Sim | F2: Sim | G2: 1 | H2: Gratuito | I2: Silencioso | J2: até 2 | K2: Entra direto | L2: Fecha 22h | M2: Segunda | N2: Casal | O2: 18–30 | P2: Romântico | Q2: Qualquer | R2: Qualquer | S2: Qualquer | T2: Qualquer | U2: Qualquer | V2: Qualquer | W2: Qualquer
A3: Igreja | B3: Bicocca | C3: Terça | D3: Recomendada | E3: Não | F3: Não | G3: 2 | H3: € | I3: Conversa fácil | J3: até 4 | K3: Até 15 min | L3: Fecha 23h | M3: Terça | N3: Família com crianças | O3: 30–50 | P3: Celebração | Q3: Casal | R3: 18–30 | S3: Romântico | T3: Gratuito | U3: Museu | V3: 5Vie | W3: Segunda
A4: Monumento | B4: Brera | C4: Quarta | D4: Obrigatória | F4: Não sei | G4: 3 | H4: €€ | I4: Animado | J4: até 6 | K4: Reservar antes | L4: Fecha 00h | M4: Quarta | N4: Solo | O4: 50+ | P4: Business | Q4: Família com crianças | R4: 30–50 | S4: Celebração | T4: € | U4: Igreja | V4: Bicocca | W4: Terça
A5: Restaurante | B5: Castello | C5: Quinta | D5: Appointment | G5: 4 | H5: €€€ | I5: Alto | J5: até 10 | K5: Lista de espera real | L5: Depois de 00h | M5: Quinta | N5: Grupo | O5: Indiferente | P5: Cultural | Q5: Solo | R5: 50+ | S5: Business | T5: €€ | U5: Monumento | V5: Brera | W5: Quarta
A6: Trattoria | B6: Centrale | C6: Sexta | G6: 5 | H6: €€€€ | J6: mais de 10 | L6: Não se aplica | M6: Sexta | N6: Negócios | P6: Sem turistas | Q6: Grupo | S6: Cultural | T6: €€€ | U6: Restaurante | V6: Castello | W6: Quinta
A7: Alta gastronomia | B7: Centro | C7: Sábado | M7: Sábado | P7: Instagram | Q7: Negócios | S7: Sem turistas | T7: €€€€ | U7: Trattoria | V7: Centrale | W7: Sexta
A8: Bar/Cocktail | B8: Chiaravalle | C8: Domingo | M8: Domingo | P8: Relax | S8: Instagram | U8: Alta gastronomia | V8: Centro | W8: Sábado
A9: Aperitivo | B9: CityLife | C9: Seg e ter | P9: Noite | S9: Relax | U9: Bar/Cocktail | V9: Chiaravalle | W9: Domingo
A10: Café/Pasticceria | B10: Corso Vercelli/Pagano | C10: Nunca | S10: Noite | U10: Aperitivo | V10: CityLife
A11: Rooftop | B11: Duomo | C11: Variável | U11: Café/Pasticceria | V11: Corso Vercelli/Pagano
A12: Hotel | B12: Fora de Milão | U12: Rooftop | V12: Duomo
A13: Loja/Moda | B13: Isola | U13: Hotel | V13: Fora de Milão
A14: Mercado | B14: Navigli | U14: Loja/Moda | V14: Isola
A15: Parque | B15: Ovest (Soderini/San Gimignano) | U15: Mercado | V15: Navigli
A16: Experiência | B16: Porta Nuova | U16: Parque | V16: Ovest (Soderini/San Gimignano)
A17: Serviço | B17: Porta Romana | U17: Experiência | V17: Porta Nuova
A18: Day trip | B18: Porta Venezia | U18: Serviço | V18: Porta Romana
B19: Portello | U19: Day trip | V19: Porta Venezia
B20: QT8 | V20: Portello
B21: Quadrilatero | V21: QT8
B22: Repubblica | V22: Quadrilatero
B23: San Siro | V23: Repubblica
B24: Sant'Ambrogio | V24: San Siro
B25: Sarpi/Monumentale | V25: Sant'Ambrogio
B26: Ticinese | V26: Sarpi/Monumentale
B27: Tortona | V27: Ticinese
V28: Tortona

Sheet Fichas
A1: Semana | B1: Nome | C1: Categoria | D1: Bairro | E1: Endereço | F1: Telefone | G1: Site | H1: Fecha | I1: Horário | J1: Reserva | K1: Transporte | L1: Visitado | M1: Data | N1: Nota | O1: Faixa | P1: Serve para | Q1: Faixa etária | R1: Ocasião | S1: Ruído | T1: Grupo | U1: Chuva | V1: LGBTQIA+ friendly | W1: Acessível | X1: Cães | Y1: Espera | Z1: Até tarde | AA1: Não indicar para | AB1: Pontos fracos | AC1: Descrição | AD1: Ponto forte | AE1: Plano B | AF1: Pontuação
A2: 1 | B2: Duomo di Milano — Catedral | C2: Monumento | D2: Duomo | E2: Piazza del Duomo | G2: duomomilano.it | H2: Nunca | I2: ~9:00–19:00 (varia) | J2: Recomendada | K2: M1/M3 Duomo | L2: Não | AF2: =IF($B2="","",IF(AND(Consulta!$B$11="Sim",$L2<>"Sim"),-9999,IF($H2=Consulta!$B$5,-9999,IF(AND(Consulta!$B$3<>"Qualquer",ISNUMBER(SEARCH(Consulta!$B$3,$AA2))),-9999,IF(AND(Consulta!$B$10="Sim",$V2<>"Sim"),-9999,IF(OR(Consulta!$B$3="Qualquer",ISNUMBER(SEARCH(Consulta!$B$3,$P2))),3,0)+IF(OR(Consulta!$B$12="Qualquer",ISNUMBER(SEARCH(Consulta!$B$12,$Q2))),2,0)+IF(OR(Consulta!$B$4="Qualquer",ISNUMBER(SEARCH(Consulta!$B$4,$R2))),3,0)+IF(Consulta!$B$6="Qualquer",0,IF($O2=Consulta!$B$6,2,-1))+IF(Consulta!$B$7="Não",0,IF($U2="Sim",3,IF($U2="Não",-6,0)))+IF(Consulta!$B$8="Qualquer",0,IF($C2=Consulta!$B$8,2,-3))+IF(Consulta!$B$9="Qualquer",0,IF($D2=Consulta!$B$9,2,-1))+IF($N2="",0,$N2)-ROW()/100000))))) -> 7.99998
A3: 1 | B3: Duomo — Terrazze (terraços) | C3: Monumento | D3: Duomo | E3: Piazza del Duomo | G3: duomomilano.it | H3: Nunca | I3: ~9:00–19:00 | J3: Recomendada | K3: M1/M3 Duomo | L3: Não | AF3: =IF($B3="","",IF(AND(Consulta!$B$11="Sim",$L3<>"Sim"),-9999,IF($H3=Consulta!$B$5,-9999,IF(AND(Consulta!$B$3<>"Qualquer",ISNUMBER(SEARCH(Consulta!$B$3,$AA3))),-9999,IF(AND(Consulta!$B$10="Sim",$V3<>"Sim"),-9999,IF(OR(Consulta!$B$3="Qualquer",ISNUMBER(SEARCH(Consulta!$B$3,$P3))),3,0)+IF(OR(Consulta!$B$12="Qualquer",ISNUMBER(SEARCH(Consulta!$B$12,$Q3))),2,0)+IF(OR(Consulta!$B$4="Qualquer",ISNUMBER(SEARCH(Consulta!$B$4,$R3))),3,0)+IF(Consulta!$B$6="Qualquer",0,IF($O3=Consulta!$B$6,2,-1))+IF(Consulta!$B$7="Não",0,IF($U3="Sim",3,IF($U3="Não",-6,0)))+IF(Consulta!$B$8="Qualquer",0,IF($C3=Consulta!$B$8,2,-3))+IF(Consulta!$B$9="Qualquer",0,IF($D3=Consulta!$B$9,2,-1))+IF($N3="",0,$N3)-ROW()/100000))))) -> 7.99997
A4: 1 | B4: Museo del Duomo | C4: Museu | D4: Duomo | E4: Piazza del Duomo 12 | G4: duomomilano.it | H4: Quarta | I4: 10:00–19:00 | J4: Não precisa | K4: M1/M3 Duomo | L4: Não | AF4: =IF($B4="","",IF(AND(Consulta!$B$11="Sim",$L4<>"Sim"),-9999,IF($H4=Consulta!$B$5,-9999,IF(AND(Consulta!$B$3<>"Qualquer",ISNUMBER(SEARCH(Consulta!$B$3,$AA4))),-9999,IF(AND(Consulta!$B$10="Sim",$V4<>"Sim"),-9999,IF(OR(Consulta!$B$3="Qualquer",ISNUMBER(SEARCH(Consulta!$B$3,$P4))),3,0)+IF(OR(Consulta!$B$12="Qualquer",ISNUMBER(SEARCH(Consulta!$B$12,$Q4))),2,0)+IF(OR(Consulta!$B$4="Qualquer",ISNUMBER(SEARCH(Consulta!$B$4,$R4))),3,0)+IF(Consulta!$B$6="Qualquer",0,IF($O4=Consulta!$B$6,2,-1))+IF(Consulta!$B$7="Não",0,IF($U4="Sim",3,IF($U4="Não",-6,0)))+IF(Consulta!$B$8="Qualquer",0,IF($C4=Consulta!$B$8,2,-3))+IF(Consulta!$B$9="Qualquer",0,IF($D4=Consulta!$B$9,2,-1))+IF($N4="",0,$N4)-ROW()/100000))))) -> 7.99996
A5: 1 | B5: Galleria Vittorio Emanuele II | C5: Monumento | D5: Duomo | E5: Piazza del Duomo | H5: Nunca | I5: Sempre aberta | J5: Não precisa | K5: M1/M3 Duomo | L5: Não | AF5: =IF($B5="","",IF(AND(Consulta!$B$11="Sim",$L5<>"Sim"),-9999,IF($H5=Consulta!$B$5,-9999,IF(AND(Consulta!$B$3<>"Qualquer",ISNUMBER(SEARCH(Consulta!$B$3,$AA5))),-9999,IF(AND(Consulta!$B$10="Sim",$V5<>"Sim"),-9999,IF(OR(Consulta!$B$3="Qualquer",ISNUMBER(SEARCH(Consulta!$B$3,$P5))),3,0)+IF(OR(Consulta!$B$12="Qualquer",ISNUMBER(SEARCH(Consulta!$B$12,$Q5))),2,0)+IF(OR(Consulta!$B$4="Qualquer",ISNUMBER(SEARCH(Consulta!$B$4,$R5))),3,0)+IF(Consulta!$B$6="Qualquer",0,IF($O5=Consulta!$B$6,2,-1))+IF(Consulta!$B$7="Não",0,IF($U5="Sim",3,IF($U5="Não",-6,0)))+IF(Consulta!$B$8="Qualquer",0,IF($C5=Consulta!$B$8,2,-3))+IF(Consulta!$B$9="Qualquer",0,IF($D5=Consulta!$B$9,2,-1))+IF($N5="",0,$N5)-ROW()/100000))))) -> 7.99995
A6: 1 | B6: Teatro alla Scala — Museo Teatrale | C6: Museu | D6: Duomo | E6: Largo Ghiringhelli 1 | G6: teatroallascala.org | H6: Nunca | I6: 9:30–17:30 (últ. 17:00) | J6: Recomendada | K6: M1 Cordusio / M3 Montenapoleone | L6: Não | AF6: =IF($B6="","",IF(AND(Consulta!$B$11="Sim",$L6<>"Sim"),-9999,IF($H6=Consulta!$B$5,-9999,IF(AND(Consulta!$B$3<>"Qualquer",ISNUMBER(SEARCH(Consulta!$B$3,$AA6))),-9999,IF(AND(Consulta!$B$10="Sim",$V6<>"Sim"),-9999,IF(OR(Consulta!$B$3="Qualquer",ISNUMBER(SEARCH(Consulta!$B$3,$P6))),3,0)+IF(OR(Consulta!$B$12="Qualquer",ISNUMBER(SEARCH(Consulta!$B$12,$Q6))),2,0)+IF(OR(Consulta!$B$4="Qualquer",ISNUMBER(SEARCH(Consulta!$B$4,$R6))),3,0)+IF(Consulta!$B$6="Qualquer",0,IF($O6=Consulta!$B$6,2,-1))+IF(Consulta!$B$7="Não",0,IF($U6="Sim",3,IF($U6="Não",-6,0)))+IF(Consulta!$B$8="Qualquer",0,IF($C6=Consulta!$B$8,2,-3))+IF(Consulta!$B$9="Qualquer",0,IF($D6=Consulta!$B$9,2,-1))+IF($N6="",0,$N6)-ROW()/100000))))) -> 7.99994
A7: 1 | B7: Museo del Novecento | C7: Museu | D7: Duomo | E7: Via Marconi 1 (Arengario) | G7: museodelnovecento.org | H7: Segunda | I7: 10:00–19:30; qui até 22:30 | J7: Recomendada | K7: M1/M3 Duomo | L7: Não | AF7: =IF($B7="","",IF(AND(Consulta!$B$11="Sim",$L7<>"Sim"),-9999,IF($H7=Consulta!$B$5,-9999,IF(AND(Consulta!$B$3<>"Qualquer",ISNUMBER(SEARCH(Consulta!$B$3,$AA7))),-9999,IF(AND(Consulta!$B$10="Sim",$V7<>"Sim"),-9999,IF(OR(Consulta!$B$3="Qualquer",ISNUMBER(SEARCH(Consulta!$B$3,$P7))),3,0)+IF(OR(Consulta!$B$12="Qualquer",ISNUMBER(SEARCH(Consulta!$B$12,$Q7))),2,0)+IF(OR(Consulta!$B$4="Qualquer",ISNUMBER(SEARCH(Consulta!$B$4,$R7))),3,0)+IF(Consulta!$B$6="Qualquer",0,IF($O7=Consulta!$B$6,2,-1))+IF(Consulta!$B$7="Não",0,IF($U7="Sim",3,IF($U7="Não",-6,0)))+IF(Consulta!$B$8="Qualquer",0,IF($C7=Consulta!$B$8,2,-3))+IF(Consulta!$B$9="Qualquer",0,IF($D7=Consulta!$B$9,2,-1))+IF($N7="",0,$N7)-ROW()/100000))))) -> 7.99993
A8: 1 | B8: Palazzo Reale | C8: Museu | D8: Duomo | E8: Piazza del Duomo 12 | H8: Segunda | I8: Varia por exposição | J8: Recomendada | K8: M1/M3 Duomo | L8: Não | AF8: =IF($B8="","",IF(AND(Consulta!$B$11="Sim",$L8<>"Sim"),-9999,IF($H8=Consulta!$B$5,-9999,IF(AND(Consulta!$B$3<>"Qualquer",ISNUMBER(SEARCH(Consulta!$B$3,$AA8))),-9999,IF(AND(Consulta!$B$10="Sim",$V8<>"Sim"),-9999,IF(OR(Consulta!$B$3="Qualquer",ISNUMBER(SEARCH(Consulta!$B$3,$P8))),3,0)+IF(OR(Consulta!$B$12="Qualquer",ISNUMBER(SEARCH(Consulta!$B$12,$Q8))),2,0)+IF(OR(Consulta!$B$4="Qualquer",ISNUMBER(SEARCH(Consulta!$B$4,$R8))),3,0)+IF(Consulta!$B$6="Qualquer",0,IF($O8=Consulta!$B$6,2,-1))+IF(Consulta!$B$7="Não",0,IF($U8="Sim",3,IF($U8="Não",-6,0)))+IF(Consulta!$B$8="Qualquer",0,IF($C8=Consulta!$B$8,2,-3))+IF(Consulta!$B$9="Qualquer",0,IF($D8=Consulta!$B$9,2,-1))+IF($N8="",0,$N8)-ROW()/100000))))) -> 7.99992
A9: 1 | B9: Gallerie d'Italia | C9: Museu | D9: Duomo | E9: Piazza della Scala 6 | G9: gallerieditalia.com | H9: Segunda | J9: Recomendada | K9: M1 Cordusio | L9: Não | AF9: =IF($B9="","",IF(AND(Consulta!$B$11="Sim",$L9<>"Sim"),-9999,IF($H9=Consulta!$B$5,-9999,IF(AND(Consulta!$B$3<>"Qualquer",ISNUMBER(SEARCH(Consulta!$B$3,$AA9))),-9999,IF(AND(Consulta!$B$10="Sim",$V9<>"Sim"),-9999,IF(OR(Consulta!$B$3="Qualquer",ISNUMBER(SEARCH(Consulta!$B$3,$P9))),3,0)+IF(OR(Consulta!$B$12="Qualquer",ISNUMBER(SEARCH(Consulta!$B$12,$Q9))),2,0)+IF(OR(Consulta!$B$4="Qualquer",ISNUMBER(SEARCH(Consulta!$B$4,$R9))),3,0)+IF(Consulta!$B$6="Qualquer",0,IF($O9=Consulta!$B$6,2,-1))+IF(Consulta!$B$7="Não",0,IF($U9="Sim",3,IF($U9="Não",-6,0)))+IF(Consulta!$B$8="Qualquer",0,IF($C9=Consulta!$B$8,2,-3))+IF(Consulta!$B$9="Qualquer",0,IF($D9=Consulta!$B$9,2,-1))+IF($N9="",0,$N9)-ROW()/100000))))) -> 7.99991
A10: 1 | B10: Camparino in Galleria | C10: Aperitivo | D10: Duomo | E10: Piazza del Duomo 21 | F10: +39 02 8646 4435 | G10: camparino.com | I10: Bar di Passo até ~23h | J10: Recomendada | K10: M1/M3 Duomo | L10: Não | AF10: =IF($B10="","",IF(AND(Consulta!$B$11="Sim",$L10<>"Sim"),-9999,IF($H10=Consulta!$B$5,-9999,IF(AND(Consulta!$B$3<>"Qualquer",ISNUMBER(SEARCH(Consulta!$B$3,$AA10))),-9999,IF(AND(Consulta!$B$10="Sim",$V10<>"Sim"),-9999,IF(OR(Consulta!$B$3="Qualquer",ISNUMBER(SEARCH(Consulta!$B$3,$P10))),3,0)+IF(OR(Consulta!$B$12="Qualquer",ISNUMBER(SEARCH(Consulta!$B$12,$Q10))),2,0)+IF(OR(Consulta!$B$4="Qualquer",ISNUMBER(SEARCH(Consulta!$B$4,$R10))),3,0)+IF(Consulta!$B$6="Qualquer",0,IF($O10=Consulta!$B$6,2,-1))+IF(Consulta!$B$7="Não",0,IF($U10="Sim",3,IF($U10="Não",-6,0)))+IF(Consulta!$B$8="Qualquer",0,IF($C10=Consulta!$B$8,2,-3))+IF(Consulta!$B$9="Qualquer",0,IF($D10=Consulta!$B$9,2,-1))+IF($N10="",0,$N10)-ROW()/100000))))) -> 7.9999
A11: 1 | B11: Marchesi 1824 | C11: Café/Pasticceria | D11: Duomo | E11: Galleria Vittorio Emanuele II | F11: +39 02 9418 1710 | G11: marchesi1824.com | J11: Não precisa | K11: M1/M3 Duomo | L11: Não | AF11: =IF($B11="","",IF(AND(Consulta!$B$11="Sim",$L11<>"Sim"),-9999,IF($H11=Consulta!$B$5,-9999,IF(AND(Consulta!$B$3<>"Qualquer",ISNUMBER(SEARCH(Consulta!$B$3,$AA11))),-9999,IF(AND(Consulta!$B$10="Sim",$V11<>"Sim"),-9999,IF(OR(Consulta!$B$3="Qualquer",ISNUMBER(SEARCH(Consulta!$B$3,$P11))),3,0)+IF(OR(Consulta!$B$12="Qualquer",ISNUMBER(SEARCH(Consulta!$B$12,$Q11))),2,0)+IF(OR(Consulta!$B$4="Qualquer",ISNUMBER(SEARCH(Consulta!$B$4,$R11))),3,0)+IF(Consulta!$B$6="Qualquer",0,IF($O11=Consulta!$B$6,2,-1))+IF(Consulta!$B$7="Não",0,IF($U11="Sim",3,IF($U11="Não",-6,0)))+IF(Consulta!$B$8="Qualquer",0,IF($C11=Consulta!$B$8,2,-3))+IF(Consulta!$B$9="Qualquer",0,IF($D11=Consulta!$B$9,2,-1))+IF($N11="",0,$N11)-ROW()/100000))))) -> 7.99989
A12: 1 | B12: Cracco | C12: Alta gastronomia | D12: Duomo | E12: Galleria Vittorio Emanuele II | F12: +39 02 876774 | G12: ristorantecracco.it | J12: Obrigatória | K12: M1/M3 Duomo | L12: Não | AF12: =IF($B12="","",IF(AND(Consulta!$B$11="Sim",$L12<>"Sim"),-9999,IF($H12=Consulta!$B$5,-9999,IF(AND(Consulta!$B$3<>"Qualquer",ISNUMBER(SEARCH(Consulta!$B$3,$AA12))),-9999,IF(AND(Consulta!$B$10="Sim",$V12<>"Sim"),-9999,IF(OR(Consulta!$B$3="Qualquer",ISNUMBER(SEARCH(Consulta!$B$3,$P12))),3,0)+IF(OR(Consulta!$B$12="Qualquer",ISNUMBER(SEARCH(Consulta!$B$12,$Q12))),2,0)+IF(OR(Consulta!$B$4="Qualquer",ISNUMBER(SEARCH(Consulta!$B$4,$R12))),3,0)+IF(Consulta!$B$6="Qualquer",0,IF($O12=Consulta!$B$6,2,-1))+IF(Consulta!$B$7="Não",0,IF($U12="Sim",3,IF($U12="Não",-6,0)))+IF(Consulta!$B$8="Qualquer",0,IF($C12=Consulta!$B$8,2,-3))+IF(Consulta!$B$9="Qualquer",0,IF($D12=Consulta!$B$9,2,-1))+IF($N12="",0,$N12)-ROW()/100000))))) -> 7.99988
A13: 1 | B13: La Rinascente + terraço | C13: Loja/Moda | D13: Duomo | E13: Piazza del Duomo | G13: rinascente.it | H13: Nunca | J13: Não precisa | K13: M1/M3 Duomo | L13: Não | AF13: =IF($B13="","",IF(AND(Consulta!$B$11="Sim",$L13<>"Sim"),-9999,IF($H13=Consulta!$B$5,-9999,IF(AND(Consulta!$B$3<>"Qualquer",ISNUMBER(SEARCH(Consulta!$B$3,$AA13))),-9999,IF(AND(Consulta!$B$10="Sim",$V13<>"Sim"),-9999,IF(OR(Consulta!$B$3="Qualquer",ISNUMBER(SEARCH(Consulta!$B$3,$P13))),3,0)+IF(OR(Consulta!$B$12="Qualquer",ISNUMBER(SEARCH(Consulta!$B$12,$Q13))),2,0)+IF(OR(Consulta!$B$4="Qualquer",ISNUMBER(SEARCH(Consulta!$B$4,$R13))),3,0)+IF(Consulta!$B$6="Qualquer",0,IF($O13=Consulta!$B$6,2,-1))+IF(Consulta!$B$7="Não",0,IF($U13="Sim",3,IF($U13="Não",-6,0)))+IF(Consulta!$B$8="Qualquer",0,IF($C13=Consulta!$B$8,2,-3))+IF(Consulta!$B$9="Qualquer",0,IF($D13=Consulta!$B$9,2,-1))+IF($N13="",0,$N13)-ROW()/100000))))) -> 7.99987
A14: 1 | B14: Piazza dei Mercanti | C14: Monumento | D14: Duomo | E14: Piazza dei Mercanti | H14: Nunca | I14: Sempre aberta | J14: Não precisa | K14: M1 Cordusio | L14: Não | AF14: =IF($B14="","",IF(AND(Consulta!$B$11="Sim",$L14<>"Sim"),-9999,IF($H14=Consulta!$B$5,-9999,IF(AND(Consulta!$B$3<>"Qualquer",ISNUMBER(SEARCH(Consulta!$B$3,$AA14))),-9999,IF(AND(Consulta!$B$10="Sim",$V14<>"Sim"),-9999,IF(OR(Consulta!$B$3="Qualquer",ISNUMBER(SEARCH(Consulta!$B$3,$P14))),3,0)+IF(OR(Consulta!$B$12="Qualquer",ISNUMBER(SEARCH(Consulta!$B$12,$Q14))),2,0)+IF(OR(Consulta!$B$4="Qualquer",ISNUMBER(SEARCH(Consulta!$B$4,$R14))),3,0)+IF(Consulta!$B$6="Qualquer",0,IF($O14=Consulta!$B$6,2,-1))+IF(Consulta!$B$7="Não",0,IF($U14="Sim",3,IF($U14="Não",-6,0)))+IF(Consulta!$B$8="Qualquer",0,IF($C14=Consulta!$B$8,2,-3))+IF(Consulta!$B$9="Qualquer",0,IF($D14=Consulta!$B$9,2,-1))+IF($N14="",0,$N14)-ROW()/100000))))) -> 7.99986
A15: 1 | B15: Park Hyatt — La Cupola / Mio Lab | C15: Hotel | D15: Duomo | E15: Via Tommaso Grossi 1 | F15: +39 02 8821 1234 | G15: hyatt.com | H15: Nunca | J15: Recomendada | K15: M1 Cordusio | L15: Não | AF15: =IF($B15="","",IF(AND(Consulta!$B$11="Sim",$L15<>"Sim"),-9999,IF($H15=Consulta!$B$5,-9999,IF(AND(Consulta!$B$3<>"Qualquer",ISNUMBER(SEARCH(Consulta!$B$3,$AA15))),-9999,IF(AND(Consulta!$B$10="Sim",$V15<>"Sim"),-9999,IF(OR(Consulta!$B$3="Qualquer",ISNUMBER(SEARCH(Consulta!$B$3,$P15))),3,0)+IF(OR(Consulta!$B$12="Qualquer",ISNUMBER(SEARCH(Consulta!$B$12,$Q15))),2,0)+IF(OR(Consulta!$B$4="Qualquer",ISNUMBER(SEARCH(Consulta!$B$4,$R15))),3,0)+IF(Consulta!$B$6="Qualquer",0,IF($O15=Consulta!$B$6,2,-1))+IF(Consulta!$B$7="Não",0,IF($U15="Sim",3,IF($U15="Não",-6,0)))+IF(Consulta!$B$8="Qualquer",0,IF($C15=Consulta!$B$8,2,-3))+IF(Consulta!$B$9="Qualquer",0,IF($D15=Consulta!$B$9,2,-1))+IF($N15="",0,$N15)-ROW()/100000))))) -> 7.99985
A16: 1 | B16: Peck | C16: Mercado | D16: Duomo | E16: Via Spadari 9 | G16: peck.it | H16: Domingo | J16: Não precisa | K16: M1/M3 Duomo | L16: Não | AF16: =IF($B16="","",IF(AND(Consulta!$B$11="Sim",$L16<>"Sim"),-9999,IF($H16=Consulta!$B$5,-9999,IF(AND(Consulta!$B$3<>"Qualquer",ISNUMBER(SEARCH(Consulta!$B$3,$AA16))),-9999,IF(AND(Consulta!$B$10="Sim",$V16<>"Sim"),-9999,IF(OR(Consulta!$B$3="Qualquer",ISNUMBER(SEARCH(Consulta!$B$3,$P16))),3,0)+IF(OR(Consulta!$B$12="Qualquer",ISNUMBER(SEARCH(Consulta!$B$12,$Q16))),2,0)+IF(OR(Consulta!$B$4="Qualquer",ISNUMBER(SEARCH(Consulta!$B$4,$R16))),3,0)+IF(Consulta!$B$6="Qualquer",0,IF($O16=Consulta!$B$6,2,-1))+IF(Consulta!$B$7="Não",0,IF($U16="Sim",3,IF($U16="Não",-6,0)))+IF(Consulta!$B$8="Qualquer",0,IF($C16=Consulta!$B$8,2,-3))+IF(Consulta!$B$9="Qualquer",0,IF($D16=Consulta!$B$9,2,-1))+IF($N16="",0,$N16)-ROW()/100000))))) -> 7.99984
A17: 2 | B17: Pinacoteca di Brera | C17: Museu | D17: Brera | E17: Via Brera 28 | G17: pinacotecabrera.org | H17: Segunda | I17: Ter–dom 8:30–19:15 (últ. 18:00) | J17: Recomendada | K17: M2 Lanza / M3 Montenapoleone | L17: Não | AF17: =IF($B17="","",IF(AND(Consulta!$B$11="Sim",$L17<>"Sim"),-9999,IF($H17=Consulta!$B$5,-9999,IF(AND(Consulta!$B$3<>"Qualquer",ISNUMBER(SEARCH(Consulta!$B$3,$AA17))),-9999,IF(AND(Consulta!$B$10="Sim",$V17<>"Sim"),-9999,IF(OR(Consulta!$B$3="Qualquer",ISNUMBER(SEARCH(Consulta!$B$3,$P17))),3,0)+IF(OR(Consulta!$B$12="Qualquer",ISNUMBER(SEARCH(Consulta!$B$12,$Q17))),2,0)+IF(OR(Consulta!$B$4="Qualquer",ISNUMBER(SEARCH(Consulta!$B$4,$R17))),3,0)+IF(Consulta!$B$6="Qualquer",0,IF($O17=Consulta!$B$6,2,-1))+IF(Consulta!$B$7="Não",0,IF($U17="Sim",3,IF($U17="Não",-6,0)))+IF(Consulta!$B$8="Qualquer",0,IF($C17=Consulta!$B$8,2,-3))+IF(Consulta!$B$9="Qualquer",0,IF($D17=Consulta!$B$9,2,-1))+IF($N17="",0,$N17)-ROW()/100000))))) -> 7.99983
A18: 2 | B18: Palazzo Citterio (Brera Modern) | C18: Museu | D18: Brera | E18: Via Brera 14 | G18: pinacotecabrera.org | H18: Segunda | J18: Recomendada | K18: M2 Lanza | L18: Não | AF18: =IF($B18="","",IF(AND(Consulta!$B$11="Sim",$L18<>"Sim"),-9999,IF($H18=Consulta!$B$5,-9999,IF(AND(Consulta!$B$3<>"Qualquer",ISNUMBER(SEARCH(Consulta!$B$3,$AA18))),-9999,IF(AND(Consulta!$B$10="Sim",$V18<>"Sim"),-9999,IF(OR(Consulta!$B$3="Qualquer",ISNUMBER(SEARCH(Consulta!$B$3,$P18))),3,0)+IF(OR(Consulta!$B$12="Qualquer",ISNUMBER(SEARCH(Consulta!$B$12,$Q18))),2,0)+IF(OR(Consulta!$B$4="Qualquer",ISNUMBER(SEARCH(Consulta!$B$4,$R18))),3,0)+IF(Consulta!$B$6="Qualquer",0,IF($O18=Consulta!$B$6,2,-1))+IF(Consulta!$B$7="Não",0,IF($U18="Sim",3,IF($U18="Não",-6,0)))+IF(Consulta!$B$8="Qualquer",0,IF($C18=Consulta!$B$8,2,-3))+IF(Consulta!$B$9="Qualquer",0,IF($D18=Consulta!$B$9,2,-1))+IF($N18="",0,$N18)-ROW()/100000))))) -> 7.99982
A19: 2 | B19: Orto Botanico di Brera | C19: Parque | D19: Brera | E19: Via Brera 28 | J19: Não precisa | K19: M2 Lanza | L19: Não | AF19: =IF($B19="","",IF(AND(Consulta!$B$11="Sim",$L19<>"Sim"),-9999,IF($H19=Consulta!$B$5,-9999,IF(AND(Consulta!$B$3<>"Qualquer",ISNUMBER(SEARCH(Consulta!$B$3,$AA19))),-9999,IF(AND(Consulta!$B$10="Sim",$V19<>"Sim"),-9999,IF(OR(Consulta!$B$3="Qualquer",ISNUMBER(SEARCH(Consulta!$B$3,$P19))),3,0)+IF(OR(Consulta!$B$12="Qualquer",ISNUMBER(SEARCH(Consulta!$B$12,$Q19))),2,0)+IF(OR(Consulta!$B$4="Qualquer",ISNUMBER(SEARCH(Consulta!$B$4,$R19))),3,0)+IF(Consulta!$B$6="Qualquer",0,IF($O19=Consulta!$B$6,2,-1))+IF(Consulta!$B$7="Não",0,IF($U19="Sim",3,IF($U19="Não",-6,0)))+IF(Consulta!$B$8="Qualquer",0,IF($C19=Consulta!$B$8,2,-3))+IF(Consulta!$B$9="Qualquer",0,IF($D19=Consulta!$B$9,2,-1))+IF($N19="",0,$N19)-ROW()/100000))))) -> 7.99981
A20: 2 | B20: Museo Poldi Pezzoli | C20: Museu | D20: Brera | E20: Via Manzoni 12 | G20: museopoldipezzoli.it | H20: Terça | I20: Seg e qua–dom 10:00–18:00 | J20: Recomendada | K20: M3 Montenapoleone | L20: Não | AF20: =IF($B20="","",IF(AND(Consulta!$B$11="Sim",$L20<>"Sim"),-9999,IF($H20=Consulta!$B$5,-9999,IF(AND(Consulta!$B$3<>"Qualquer",ISNUMBER(SEARCH(Consulta!$B$3,$AA20))),-9999,IF(AND(Consulta!$B$10="Sim",$V20<>"Sim"),-9999,IF(OR(Consulta!$B$3="Qualquer",ISNUMBER(SEARCH(Consulta!$B$3,$P20))),3,0)+IF(OR(Consulta!$B$12="Qualquer",ISNUMBER(SEARCH(Consulta!$B$12,$Q20))),2,0)+IF(OR(Consulta!$B$4="Qualquer",ISNUMBER(SEARCH(Consulta!$B$4,$R20))),3,0)+IF(Consulta!$B$6="Qualquer",0,IF($O20=Consulta!$B$6,2,-1))+IF(Consulta!$B$7="Não",0,IF($U20="Sim",3,IF($U20="Não",-6,0)))+IF(Consulta!$B$8="Qualquer",0,IF($C20=Consulta!$B$8,2,-3))+IF(Consulta!$B$9="Qualquer",0,IF($D20=Consulta!$B$9,2,-1))+IF($N20="",0,$N20)-ROW()/100000))))) -> 7.9998
A21: 2 | B21: Casa Brera — rooftop Etereo | C21: Rooftop | D21: Brera | E21: Piazzetta M. Bossi 2 | F21: +39 02 305430 | G21: marriott.com | H21: Nunca | I21: Bar 17:00–01:00 | J21: Obrigatória | K21: M1 Cairoli / M3 Montenapoleone | L21: Não | AF21: =IF($B21="","",IF(AND(Consulta!$B$11="Sim",$L21<>"Sim"),-9999,IF($H21=Consulta!$B$5,-9999,IF(AND(Consulta!$B$3<>"Qualquer",ISNUMBER(SEARCH(Consulta!$B$3,$AA21))),-9999,IF(AND(Consulta!$B$10="Sim",$V21<>"Sim"),-9999,IF(OR(Consulta!$B$3="Qualquer",ISNUMBER(SEARCH(Consulta!$B$3,$P21))),3,0)+IF(OR(Consulta!$B$12="Qualquer",ISNUMBER(SEARCH(Consulta!$B$12,$Q21))),2,0)+IF(OR(Consulta!$B$4="Qualquer",ISNUMBER(SEARCH(Consulta!$B$4,$R21))),3,0)+IF(Consulta!$B$6="Qualquer",0,IF($O21=Consulta!$B$6,2,-1))+IF(Consulta!$B$7="Não",0,IF($U21="Sim",3,IF($U21="Não",-6,0)))+IF(Consulta!$B$8="Qualquer",0,IF($C21=Consulta!$B$8,2,-3))+IF(Consulta!$B$9="Qualquer",0,IF($D21=Consulta!$B$9,2,-1))+IF($N21="",0,$N21)-ROW()/100000))))) -> 7.99979
A22: 2 | B22: Bulgari Hotel — Bar e jardim | C22: Hotel | D22: Brera | E22: Via Privata Fratelli Gabba 7/b | F22: +39 02 805 8051 | G22: bulgarihotels.com | H22: Nunca | J22: Recomendada | K22: M3 Montenapoleone | L22: Não | AF22: =IF($B22="","",IF(AND(Consulta!$B$11="Sim",$L22<>"Sim"),-9999,IF($H22=Consulta!$B$5,-9999,IF(AND(Consulta!$B$3<>"Qualquer",ISNUMBER(SEARCH(Consulta!$B$3,$AA22))),-9999,IF(AND(Consulta!$B$10="Sim",$V22<>"Sim"),-9999,IF(OR(Consulta!$B$3="Qualquer",ISNUMBER(SEARCH(Consulta!$B$3,$P22))),3,0)+IF(OR(Consulta!$B$12="Qualquer",ISNUMBER(SEARCH(Consulta!$B$12,$Q22))),2,0)+IF(OR(Consulta!$B$4="Qualquer",ISNUMBER(SEARCH(Consulta!$B$4,$R22))),3,0)+IF(Consulta!$B$6="Qualquer",0,IF($O22=Consulta!$B$6,2,-1))+IF(Consulta!$B$7="Não",0,IF($U22="Sim",3,IF($U22="Não",-6,0)))+IF(Consulta!$B$8="Qualquer",0,IF($C22=Consulta!$B$8,2,-3))+IF(Consulta!$B$9="Qualquer",0,IF($D22=Consulta!$B$9,2,-1))+IF($N22="",0,$N22)-ROW()/100000))))) -> 7.99978
A23: 2 | B23: Mandarin Oriental — Seta / bar | C23: Hotel | D23: Brera | E23: Via Andegari 9 | F23: +39 02 8731 8888 | G23: mandarinoriental.com | H23: Nunca | J23: Obrigatória | K23: M3 Montenapoleone | L23: Não | AF23: =IF($B23="","",IF(AND(Consulta!$B$11="Sim",$L23<>"Sim"),-9999,IF($H23=Consulta!$B$5,-9999,IF(AND(Consulta!$B$3<>"Qualquer",ISNUMBER(SEARCH(Consulta!$B$3,$AA23))),-9999,IF(AND(Consulta!$B$10="Sim",$V23<>"Sim"),-9999,IF(OR(Consulta!$B$3="Qualquer",ISNUMBER(SEARCH(Consulta!$B$3,$P23))),3,0)+IF(OR(Consulta!$B$12="Qualquer",ISNUMBER(SEARCH(Consulta!$B$12,$Q23))),2,0)+IF(OR(Consulta!$B$4="Qualquer",ISNUMBER(SEARCH(Consulta!$B$4,$R23))),3,0)+IF(Consulta!$B$6="Qualquer",0,IF($O23=Consulta!$B$6,2,-1))+IF(Consulta!$B$7="Não",0,IF($U23="Sim",3,IF($U23="Não",-6,0)))+IF(Consulta!$B$8="Qualquer",0,IF($C23=Consulta!$B$8,2,-3))+IF(Consulta!$B$9="Qualquer",0,IF($D23=Consulta!$B$9,2,-1))+IF($N23="",0,$N23)-ROW()/100000))))) -> 7.99977
A24: 2 | B24: Via Fiori Chiari / Via Madonnina | C24: Experiência | D24: Brera | E24: Brera | H24: Nunca | J24: Não precisa | K24: M2 Lanza | L24: Não | AF24: =IF($B24="","",IF(AND(Consulta!$B$11="Sim",$L24<>"Sim"),-9999,IF($H24=Consulta!$B$5,-9999,IF(AND(Consulta!$B$3<>"Qualquer",ISNUMBER(SEARCH(Consulta!$B$3,$AA24))),-9999,IF(AND(Consulta!$B$10="Sim",$V24<>"Sim"),-9999,IF(OR(Consulta!$B$3="Qualquer",ISNUMBER(SEARCH(Consulta!$B$3,$P24))),3,0)+IF(OR(Consulta!$B$12="Qualquer",ISNUMBER(SEARCH(Consulta!$B$12,$Q24))),2,0)+IF(OR(Consulta!$B$4="Qualquer",ISNUMBER(SEARCH(Consulta!$B$4,$R24))),3,0)+IF(Consulta!$B$6="Qualquer",0,IF($O24=Consulta!$B$6,2,-1))+IF(Consulta!$B$7="Não",0,IF($U24="Sim",3,IF($U24="Não",-6,0)))+IF(Consulta!$B$8="Qualquer",0,IF($C24=Consulta!$B$8,2,-3))+IF(Consulta!$B$9="Qualquer",0,IF($D24=Consulta!$B$9,2,-1))+IF($N24="",0,$N24)-ROW()/100000))))) -> 7.99976
A25: 2 | B25: Mercato antiquariato di Brera | C25: Mercado | D25: Brera | E25: Via Fiori Chiari | I25: 3º domingo do mês (confirmar) | J25: Não precisa | K25: M2 Lanza | L25: Não | AF25: =IF($B25="","",IF(AND(Consulta!$B$11="Sim",$L25<>"Sim"),-9999,IF($H25=Consulta!$B$5,-9999,IF(AND(Consulta!$B$3<>"Qualquer",ISNUMBER(SEARCH(Consulta!$B$3,$AA25))),-9999,IF(AND(Consulta!$B$10="Sim",$V25<>"Sim"),-9999,IF(OR(Consulta!$B$3="Qualquer",ISNUMBER(SEARCH(Consulta!$B$3,$P25))),3,0)+IF(OR(Consulta!$B$12="Qualquer",ISNUMBER(SEARCH(Consulta!$B$12,$Q25))),2,0)+IF(OR(Consulta!$B$4="Qualquer",ISNUMBER(SEARCH(Consulta!$B$4,$R25))),3,0)+IF(Consulta!$B$6="Qualquer",0,IF($O25=Consulta!$B$6,2,-1))+IF(Consulta!$B$7="Não",0,IF($U25="Sim",3,IF($U25="Não",-6,0)))+IF(Consulta!$B$8="Qualquer",0,IF($C25=Consulta!$B$8,2,-3))+IF(Consulta!$B$9="Qualquer",0,IF($D25=Consulta!$B$9,2,-1))+IF($N25="",0,$N25)-ROW()/100000))))) -> 7.99975
A26: 2 | B26: Grand Hotel et de Milan | C26: Hotel | D26: Brera | E26: Via Manzoni 29 | G26: grandhoteletdemilan.it | H26: Nunca | J26: Recomendada | K26: M3 Montenapoleone | L26: Não | AF26: =IF($B26="","",IF(AND(Consulta!$B$11="Sim",$L26<>"Sim"),-9999,IF($H26=Consulta!$B$5,-9999,IF(AND(Consulta!$B$3<>"Qualquer",ISNUMBER(SEARCH(Consulta!$B$3,$AA26))),-9999,IF(AND(Consulta!$B$10="Sim",$V26<>"Sim"),-9999,IF(OR(Consulta!$B$3="Qualquer",ISNUMBER(SEARCH(Consulta!$B$3,$P26))),3,0)+IF(OR(Consulta!$B$12="Qualquer",ISNUMBER(SEARCH(Consulta!$B$12,$Q26))),2,0)+IF(OR(Consulta!$B$4="Qualquer",ISNUMBER(SEARCH(Consulta!$B$4,$R26))),3,0)+IF(Consulta!$B$6="Qualquer",0,IF($O26=Consulta!$B$6,2,-1))+IF(Consulta!$B$7="Não",0,IF($U26="Sim",3,IF($U26="Não",-6,0)))+IF(Consulta!$B$8="Qualquer",0,IF($C26=Consulta!$B$8,2,-3))+IF(Consulta!$B$9="Qualquer",0,IF($D26=Consulta!$B$9,2,-1))+IF($N26="",0,$N26)-ROW()/100000))))) -> 7.99974
A27: 3 | B27: Cenacolo Vinciano (A Última Ceia) | C27: Museu | D27: Sant'Ambrogio | E27: Piazza Santa Maria delle Grazie 2 | F27: +39 02 9280 0360 | G27: cenacolovinciano.org | H27: Segunda | I27: Ter–dom 8:15–19:00 (últ. 18:45) | J27: Obrigatória | K27: M1 Conciliazione / M2 Sant'Ambrogio | L27: Não | AF27: =IF($B27="","",IF(AND(Consulta!$B$11="Sim",$L27<>"Sim"),-9999,IF($H27=Consulta!$B$5,-9999,IF(AND(Consulta!$B$3<>"Qualquer",ISNUMBER(SEARCH(Consulta!$B$3,$AA27))),-9999,IF(AND(Consulta!$B$10="Sim",$V27<>"Sim"),-9999,IF(OR(Consulta!$B$3="Qualquer",ISNUMBER(SEARCH(Consulta!$B$3,$P27))),3,0)+IF(OR(Consulta!$B$12="Qualquer",ISNUMBER(SEARCH(Consulta!$B$12,$Q27))),2,0)+IF(OR(Consulta!$B$4="Qualquer",ISNUMBER(SEARCH(Consulta!$B$4,$R27))),3,0)+IF(Consulta!$B$6="Qualquer",0,IF($O27=Consulta!$B$6,2,-1))+IF(Consulta!$B$7="Não",0,IF($U27="Sim",3,IF($U27="Não",-6,0)))+IF(Consulta!$B$8="Qualquer",0,IF($C27=Consulta!$B$8,2,-3))+IF(Consulta!$B$9="Qualquer",0,IF($D27=Consulta!$B$9,2,-1))+IF($N27="",0,$N27)-ROW()/100000))))) -> 7.99973
A28: 3 | B28: Santa Maria delle Grazie (igreja) | C28: Igreja | D28: Sant'Ambrogio | E28: Piazza Santa Maria delle Grazie | J28: Não precisa | K28: M1 Conciliazione | L28: Não | AF28: =IF($B28="","",IF(AND(Consulta!$B$11="Sim",$L28<>"Sim"),-9999,IF($H28=Consulta!$B$5,-9999,IF(AND(Consulta!$B$3<>"Qualquer",ISNUMBER(SEARCH(Consulta!$B$3,$AA28))),-9999,IF(AND(Consulta!$B$10="Sim",$V28<>"Sim"),-9999,IF(OR(Consulta!$B$3="Qualquer",ISNUMBER(SEARCH(Consulta!$B$3,$P28))),3,0)+IF(OR(Consulta!$B$12="Qualquer",ISNUMBER(SEARCH(Consulta!$B$12,$Q28))),2,0)+IF(OR(Consulta!$B$4="Qualquer",ISNUMBER(SEARCH(Consulta!$B$4,$R28))),3,0)+IF(Consulta!$B$6="Qualquer",0,IF($O28=Consulta!$B$6,2,-1))+IF(Consulta!$B$7="Não",0,IF($U28="Sim",3,IF($U28="Não",-6,0)))+IF(Consulta!$B$8="Qualquer",0,IF($C28=Consulta!$B$8,2,-3))+IF(Consulta!$B$9="Qualquer",0,IF($D28=Consulta!$B$9,2,-1))+IF($N28="",0,$N28)-ROW()/100000))))) -> 7.99972
A29: 3 | B29: Pinacoteca Ambrosiana + Codex Atlanticus | C29: Museu | D29: 5Vie | E29: Piazza Pio XI 2 | G29: ambrosiana.it | H29: Quarta | I29: 10:00–18:00 | J29: Recomendada | K29: M1/M3 Duomo | L29: Não | AF29: =IF($B29="","",IF(AND(Consulta!$B$11="Sim",$L29<>"Sim"),-9999,IF($H29=Consulta!$B$5,-9999,IF(AND(Consulta!$B$3<>"Qualquer",ISNUMBER(SEARCH(Consulta!$B$3,$AA29))),-9999,IF(AND(Consulta!$B$10="Sim",$V29<>"Sim"),-9999,IF(OR(Consulta!$B$3="Qualquer",ISNUMBER(SEARCH(Consulta!$B$3,$P29))),3,0)+IF(OR(Consulta!$B$12="Qualquer",ISNUMBER(SEARCH(Consulta!$B$12,$Q29))),2,0)+IF(OR(Consulta!$B$4="Qualquer",ISNUMBER(SEARCH(Consulta!$B$4,$R29))),3,0)+IF(Consulta!$B$6="Qualquer",0,IF($O29=Consulta!$B$6,2,-1))+IF(Consulta!$B$7="Não",0,IF($U29="Sim",3,IF($U29="Não",-6,0)))+IF(Consulta!$B$8="Qualquer",0,IF($C29=Consulta!$B$8,2,-3))+IF(Consulta!$B$9="Qualquer",0,IF($D29=Consulta!$B$9,2,-1))+IF($N29="",0,$N29)-ROW()/100000))))) -> 7.99971
A30: 3 | B30: Cripta di San Sepolcro | C30: Igreja | D30: 5Vie | E30: Piazza San Sepolcro | G30: ambrosiana.it | J30: Recomendada | K30: M1 Cordusio | L30: Não | AF30: =IF($B30="","",IF(AND(Consulta!$B$11="Sim",$L30<>"Sim"),-9999,IF($H30=Consulta!$B$5,-9999,IF(AND(Consulta!$B$3<>"Qualquer",ISNUMBER(SEARCH(Consulta!$B$3,$AA30))),-9999,IF(AND(Consulta!$B$10="Sim",$V30<>"Sim"),-9999,IF(OR(Consulta!$B$3="Qualquer",ISNUMBER(SEARCH(Consulta!$B$3,$P30))),3,0)+IF(OR(Consulta!$B$12="Qualquer",ISNUMBER(SEARCH(Consulta!$B$12,$Q30))),2,0)+IF(OR(Consulta!$B$4="Qualquer",ISNUMBER(SEARCH(Consulta!$B$4,$R30))),3,0)+IF(Consulta!$B$6="Qualquer",0,IF($O30=Consulta!$B$6,2,-1))+IF(Consulta!$B$7="Não",0,IF($U30="Sim",3,IF($U30="Não",-6,0)))+IF(Consulta!$B$8="Qualquer",0,IF($C30=Consulta!$B$8,2,-3))+IF(Consulta!$B$9="Qualquer",0,IF($D30=Consulta!$B$9,2,-1))+IF($N30="",0,$N30)-ROW()/100000))))) -> 7.9997
A31: 3 | B31: Castello Sforzesco — Sala delle Asse e Pietà Rondanini | C31: Museu | D31: Castello | E31: Piazza Castello | G31: comune.milano.it | H31: Segunda | I31: Museus ter–dom 10:00–17:30; pátios 7:00–19:30 | J31: Não precisa | K31: M1 Cairoli / M2 Lanza | L31: Não | AF31: =IF($B31="","",IF(AND(Consulta!$B$11="Sim",$L31<>"Sim"),-9999,IF($H31=Consulta!$B$5,-9999,IF(AND(Consulta!$B$3<>"Qualquer",ISNUMBER(SEARCH(Consulta!$B$3,$AA31))),-9999,IF(AND(Consulta!$B$10="Sim",$V31<>"Sim"),-9999,IF(OR(Consulta!$B$3="Qualquer",ISNUMBER(SEARCH(Consulta!$B$3,$P31))),3,0)+IF(OR(Consulta!$B$12="Qualquer",ISNUMBER(SEARCH(Consulta!$B$12,$Q31))),2,0)+IF(OR(Consulta!$B$4="Qualquer",ISNUMBER(SEARCH(Consulta!$B$4,$R31))),3,0)+IF(Consulta!$B$6="Qualquer",0,IF($O31=Consulta!$B$6,2,-1))+IF(Consulta!$B$7="Não",0,IF($U31="Sim",3,IF($U31="Não",-6,0)))+IF(Consulta!$B$8="Qualquer",0,IF($C31=Consulta!$B$8,2,-3))+IF(Consulta!$B$9="Qualquer",0,IF($D31=Consulta!$B$9,2,-1))+IF($N31="",0,$N31)-ROW()/100000))))) -> 7.99969
A32: 3 | B32: Museo Naz. della Scienza e della Tecnologia Leonardo da Vinci | C32: Museu | D32: Sant'Ambrogio | E32: Via San Vittore 21 | G32: museoscienza.org | H32: Segunda | J32: Recomendada | K32: M2 Sant'Ambrogio | L32: Não | AF32: =IF($B32="","",IF(AND(Consulta!$B$11="Sim",$L32<>"Sim"),-9999,IF($H32=Consulta!$B$5,-9999,IF(AND(Consulta!$B$3<>"Qualquer",ISNUMBER(SEARCH(Consulta!$B$3,$AA32))),-9999,IF(AND(Consulta!$B$10="Sim",$V32<>"Sim"),-9999,IF(OR(Consulta!$B$3="Qualquer",ISNUMBER(SEARCH(Consulta!$B$3,$P32))),3,0)+IF(OR(Consulta!$B$12="Qualquer",ISNUMBER(SEARCH(Consulta!$B$12,$Q32))),2,0)+IF(OR(Consulta!$B$4="Qualquer",ISNUMBER(SEARCH(Consulta!$B$4,$R32))),3,0)+IF(Consulta!$B$6="Qualquer",0,IF($O32=Consulta!$B$6,2,-1))+IF(Consulta!$B$7="Não",0,IF($U32="Sim",3,IF($U32="Não",-6,0)))+IF(Consulta!$B$8="Qualquer",0,IF($C32=Consulta!$B$8,2,-3))+IF(Consulta!$B$9="Qualquer",0,IF($D32=Consulta!$B$9,2,-1))+IF($N32="",0,$N32)-ROW()/100000))))) -> 7.99968
A33: 3 | B33: San Maurizio al Monastero Maggiore | C33: Igreja | D33: Sant'Ambrogio | E33: Corso Magenta 15 | J33: Não precisa | K33: M1 Cadorna | L33: Não | AF33: =IF($B33="","",IF(AND(Consulta!$B$11="Sim",$L33<>"Sim"),-9999,IF($H33=Consulta!$B$5,-9999,IF(AND(Consulta!$B$3<>"Qualquer",ISNUMBER(SEARCH(Consulta!$B$3,$AA33))),-9999,IF(AND(Consulta!$B$10="Sim",$V33<>"Sim"),-9999,IF(OR(Consulta!$B$3="Qualquer",ISNUMBER(SEARCH(Consulta!$B$3,$P33))),3,0)+IF(OR(Consulta!$B$12="Qualquer",ISNUMBER(SEARCH(Consulta!$B$12,$Q33))),2,0)+IF(OR(Consulta!$B$4="Qualquer",ISNUMBER(SEARCH(Consulta!$B$4,$R33))),3,0)+IF(Consulta!$B$6="Qualquer",0,IF($O33=Consulta!$B$6,2,-1))+IF(Consulta!$B$7="Não",0,IF($U33="Sim",3,IF($U33="Não",-6,0)))+IF(Consulta!$B$8="Qualquer",0,IF($C33=Consulta!$B$8,2,-3))+IF(Consulta!$B$9="Qualquer",0,IF($D33=Consulta!$B$9,2,-1))+IF($N33="",0,$N33)-ROW()/100000))))) -> 7.99967
A34: 3 | B34: Museo Archeologico | C34: Museu | D34: Sant'Ambrogio | E34: Corso Magenta 15 | H34: Segunda | J34: Não precisa | K34: M1 Cadorna | L34: Não | AF34: =IF($B34="","",IF(AND(Consulta!$B$11="Sim",$L34<>"Sim"),-9999,IF($H34=Consulta!$B$5,-9999,IF(AND(Consulta!$B$3<>"Qualquer",ISNUMBER(SEARCH(Consulta!$B$3,$AA34))),-9999,IF(AND(Consulta!$B$10="Sim",$V34<>"Sim"),-9999,IF(OR(Consulta!$B$3="Qualquer",ISNUMBER(SEARCH(Consulta!$B$3,$P34))),3,0)+IF(OR(Consulta!$B$12="Qualquer",ISNUMBER(SEARCH(Consulta!$B$12,$Q34))),2,0)+IF(OR(Consulta!$B$4="Qualquer",ISNUMBER(SEARCH(Consulta!$B$4,$R34))),3,0)+IF(Consulta!$B$6="Qualquer",0,IF($O34=Consulta!$B$6,2,-1))+IF(Consulta!$B$7="Não",0,IF($U34="Sim",3,IF($U34="Não",-6,0)))+IF(Consulta!$B$8="Qualquer",0,IF($C34=Consulta!$B$8,2,-3))+IF(Consulta!$B$9="Qualquer",0,IF($D34=Consulta!$B$9,2,-1))+IF($N34="",0,$N34)-ROW()/100000))))) -> 7.99966
A35: 4 | B35: Santa Maria presso San Satiro (falso coro de Bramante) | C35: Igreja | D35: 5Vie | E35: Via Torino 9 | J35: Não precisa | K35: M1/M3 Duomo | L35: Não | AF35: =IF($B35="","",IF(AND(Consulta!$B$11="Sim",$L35<>"Sim"),-9999,IF($H35=Consulta!$B$5,-9999,IF(AND(Consulta!$B$3<>"Qualquer",ISNUMBER(SEARCH(Consulta!$B$3,$AA35))),-9999,IF(AND(Consulta!$B$10="Sim",$V35<>"Sim"),-9999,IF(OR(Consulta!$B$3="Qualquer",ISNUMBER(SEARCH(Consulta!$B$3,$P35))),3,0)+IF(OR(Consulta!$B$12="Qualquer",ISNUMBER(SEARCH(Consulta!$B$12,$Q35))),2,0)+IF(OR(Consulta!$B$4="Qualquer",ISNUMBER(SEARCH(Consulta!$B$4,$R35))),3,0)+IF(Consulta!$B$6="Qualquer",0,IF($O35=Consulta!$B$6,2,-1))+IF(Consulta!$B$7="Não",0,IF($U35="Sim",3,IF($U35="Não",-6,0)))+IF(Consulta!$B$8="Qualquer",0,IF($C35=Consulta!$B$8,2,-3))+IF(Consulta!$B$9="Qualquer",0,IF($D35=Consulta!$B$9,2,-1))+IF($N35="",0,$N35)-ROW()/100000))))) -> 7.99965
A36: 4 | B36: San Bernardino alle Ossa (ossário) | C36: Igreja | D36: Centro | E36: Piazza Santo Stefano | J36: Não precisa | K36: M1 San Babila | L36: Não | AF36: =IF($B36="","",IF(AND(Consulta!$B$11="Sim",$L36<>"Sim"),-9999,IF($H36=Consulta!$B$5,-9999,IF(AND(Consulta!$B$3<>"Qualquer",ISNUMBER(SEARCH(Consulta!$B$3,$AA36))),-9999,IF(AND(Consulta!$B$10="Sim",$V36<>"Sim"),-9999,IF(OR(Consulta!$B$3="Qualquer",ISNUMBER(SEARCH(Consulta!$B$3,$P36))),3,0)+IF(OR(Consulta!$B$12="Qualquer",ISNUMBER(SEARCH(Consulta!$B$12,$Q36))),2,0)+IF(OR(Consulta!$B$4="Qualquer",ISNUMBER(SEARCH(Consulta!$B$4,$R36))),3,0)+IF(Consulta!$B$6="Qualquer",0,IF($O36=Consulta!$B$6,2,-1))+IF(Consulta!$B$7="Não",0,IF($U36="Sim",3,IF($U36="Não",-6,0)))+IF(Consulta!$B$8="Qualquer",0,IF($C36=Consulta!$B$8,2,-3))+IF(Consulta!$B$9="Qualquer",0,IF($D36=Consulta!$B$9,2,-1))+IF($N36="",0,$N36)-ROW()/100000))))) -> 7.99964
A37: 4 | B37: Casa degli Omenoni | C37: Monumento | D37: Centro | E37: Via Omenoni | H37: Nunca | I37: Só exterior | J37: Não precisa | K37: M1/M3 Duomo | L37: Não | AF37: =IF($B37="","",IF(AND(Consulta!$B$11="Sim",$L37<>"Sim"),-9999,IF($H37=Consulta!$B$5,-9999,IF(AND(Consulta!$B$3<>"Qualquer",ISNUMBER(SEARCH(Consulta!$B$3,$AA37))),-9999,IF(AND(Consulta!$B$10="Sim",$V37<>"Sim"),-9999,IF(OR(Consulta!$B$3="Qualquer",ISNUMBER(SEARCH(Consulta!$B$3,$P37))),3,0)+IF(OR(Consulta!$B$12="Qualquer",ISNUMBER(SEARCH(Consulta!$B$12,$Q37))),2,0)+IF(OR(Consulta!$B$4="Qualquer",ISNUMBER(SEARCH(Consulta!$B$4,$R37))),3,0)+IF(Consulta!$B$6="Qualquer",0,IF($O37=Consulta!$B$6,2,-1))+IF(Consulta!$B$7="Não",0,IF($U37="Sim",3,IF($U37="Não",-6,0)))+IF(Consulta!$B$8="Qualquer",0,IF($C37=Consulta!$B$8,2,-3))+IF(Consulta!$B$9="Qualquer",0,IF($D37=Consulta!$B$9,2,-1))+IF($N37="",0,$N37)-ROW()/100000))))) -> 7.99963
A38: 4 | B38: Via Lincoln (a 'Burano' milanesa) | C38: Experiência | D38: Porta Venezia | E38: Via Lincoln | H38: Nunca | J38: Não precisa | K38: M1 Porta Venezia | L38: Não | AF38: =IF($B38="","",IF(AND(Consulta!$B$11="Sim",$L38<>"Sim"),-9999,IF($H38=Consulta!$B$5,-9999,IF(AND(Consulta!$B$3<>"Qualquer",ISNUMBER(SEARCH(Consulta!$B$3,$AA38))),-9999,IF(AND(Consulta!$B$10="Sim",$V38<>"Sim"),-9999,IF(OR(Consulta!$B$3="Qualquer",ISNUMBER(SEARCH(Consulta!$B$3,$P38))),3,0)+IF(OR(Consulta!$B$12="Qualquer",ISNUMBER(SEARCH(Consulta!$B$12,$Q38))),2,0)+IF(OR(Consulta!$B$4="Qualquer",ISNUMBER(SEARCH(Consulta!$B$4,$R38))),3,0)+IF(Consulta!$B$6="Qualquer",0,IF($O38=Consulta!$B$6,2,-1))+IF(Consulta!$B$7="Não",0,IF($U38="Sim",3,IF($U38="Não",-6,0)))+IF(Consulta!$B$8="Qualquer",0,IF($C38=Consulta!$B$8,2,-3))+IF(Consulta!$B$9="Qualquer",0,IF($D38=Consulta!$B$9,2,-1))+IF($N38="",0,$N38)-ROW()/100000))))) -> 7.99962
A39: 4 | B39: Villa Invernizzi (flamingos) | C39: Experiência | D39: Porta Venezia | E39: Via Cappuccini 7 | H39: Nunca | I39: Jardim privado, vista da rua | J39: Não precisa | K39: M1 Palestro | L39: Não | AF39: =IF($B39="","",IF(AND(Consulta!$B$11="Sim",$L39<>"Sim"),-9999,IF($H39=Consulta!$B$5,-9999,IF(AND(Consulta!$B$3<>"Qualquer",ISNUMBER(SEARCH(Consulta!$B$3,$AA39))),-9999,IF(AND(Consulta!$B$10="Sim",$V39<>"Sim"),-9999,IF(OR(Consulta!$B$3="Qualquer",ISNUMBER(SEARCH(Consulta!$B$3,$P39))),3,0)+IF(OR(Consulta!$B$12="Qualquer",ISNUMBER(SEARCH(Consulta!$B$12,$Q39))),2,0)+IF(OR(Consulta!$B$4="Qualquer",ISNUMBER(SEARCH(Consulta!$B$4,$R39))),3,0)+IF(Consulta!$B$6="Qualquer",0,IF($O39=Consulta!$B$6,2,-1))+IF(Consulta!$B$7="Não",0,IF($U39="Sim",3,IF($U39="Não",-6,0)))+IF(Consulta!$B$8="Qualquer",0,IF($C39=Consulta!$B$8,2,-3))+IF(Consulta!$B$9="Qualquer",0,IF($D39=Consulta!$B$9,2,-1))+IF($N39="",0,$N39)-ROW()/100000))))) -> 7.99961
A40: 4 | B40: Casa 770 | C40: Monumento | D40: Porta Venezia | E40: Via Poerio 35 | H40: Nunca | I40: Só exterior | J40: Não precisa | K40: M1 Porta Venezia | L40: Não | AF40: =IF($B40="","",IF(AND(Consulta!$B$11="Sim",$L40<>"Sim"),-9999,IF($H40=Consulta!$B$5,-9999,IF(AND(Consulta!$B$3<>"Qualquer",ISNUMBER(SEARCH(Consulta!$B$3,$AA40))),-9999,IF(AND(Consulta!$B$10="Sim",$V40<>"Sim"),-9999,IF(OR(Consulta!$B$3="Qualquer",ISNUMBER(SEARCH(Consulta!$B$3,$P40))),3,0)+IF(OR(Consulta!$B$12="Qualquer",ISNUMBER(SEARCH(Consulta!$B$12,$Q40))),2,0)+IF(OR(Consulta!$B$4="Qualquer",ISNUMBER(SEARCH(Consulta!$B$4,$R40))),3,0)+IF(Consulta!$B$6="Qualquer",0,IF($O40=Consulta!$B$6,2,-1))+IF(Consulta!$B$7="Não",0,IF($U40="Sim",3,IF($U40="Não",-6,0)))+IF(Consulta!$B$8="Qualquer",0,IF($C40=Consulta!$B$8,2,-3))+IF(Consulta!$B$9="Qualquer",0,IF($D40=Consulta!$B$9,2,-1))+IF($N40="",0,$N40)-ROW()/100000))))) -> 7.9996
...

Sheet Progresso
A1: Progresso das 12 semanas
A3: Semana | B3: Tema | C3: Total | D3: Visitados | E3: Falta | F3: % concluído
A4: 1 | B4: Centro | C4: =COUNTIF(Fichas!$A$2:$A$260,$A4) -> 15 | D4: =COUNTIFS(Fichas!$A$2:$A$260,$A4,Fichas!$L$2:$L$260,"Sim") -> 0 | E4: =C4-D4 -> 15 | F4: =IFERROR(D4/C4,0) -> 0
A5: 2 | B5: Brera | C5: =COUNTIF(Fichas!$A$2:$A$260,$A5) -> 10 | D5: =COUNTIFS(Fichas!$A$2:$A$260,$A5,Fichas!$L$2:$L$260,"Sim") -> 0 | E5: =C5-D5 -> 10 | F5: =IFERROR(D5/C5,0) -> 0
A6: 3 | B6: Leonardo | C6: =COUNTIF(Fichas!$A$2:$A$260,$A6) -> 8 | D6: =COUNTIFS(Fichas!$A$2:$A$260,$A6,Fichas!$L$2:$L$260,"Sim") -> 0 | E6: =C6-D6 -> 8 | F6: =IFERROR(D6/C6,0) -> 0
A7: 4 | B7: Milão secreta | C7: =COUNTIF(Fichas!$A$2:$A$260,$A7) -> 12 | D7: =COUNTIFS(Fichas!$A$2:$A$260,$A7,Fichas!$L$2:$L$260,"Sim") -> 0 | E7: =C7-D7 -> 12 | F7: =IFERROR(D7/C7,0) -> 0
A8: 5 | B8: Moda | C8: =COUNTIF(Fichas!$A$2:$A$260,$A8) -> 10 | D8: =COUNTIFS(Fichas!$A$2:$A$260,$A8,Fichas!$L$2:$L$260,"Sim") -> 0 | E8: =C8-D8 -> 10 | F8: =IFERROR(D8/C8,0) -> 0
A9: 6 | B9: Design | C9: =COUNTIF(Fichas!$A$2:$A$260,$A9) -> 8 | D9: =COUNTIFS(Fichas!$A$2:$A$260,$A9,Fichas!$L$2:$L$260,"Sim") -> 0 | E9: =C9-D9 -> 8 | F9: =IFERROR(D9/C9,0) -> 0
A10: 7 | B10: Porta Venezia | C10: =COUNTIF(Fichas!$A$2:$A$260,$A10) -> 12 | D10: =COUNTIFS(Fichas!$A$2:$A$260,$A10,Fichas!$L$2:$L$260,"Sim") -> 0 | E10: =C10-D10 -> 12 | F10: =IFERROR(D10/C10,0) -> 0
A11: 8 | B11: Porta Romana / Ticinese | C11: =COUNTIF(Fichas!$A$2:$A$260,$A11) -> 9 | D11: =COUNTIFS(Fichas!$A$2:$A$260,$A11,Fichas!$L$2:$L$260,"Sim") -> 0 | E11: =C11-D11 -> 9 | F11: =IFERROR(D11/C11,0) -> 0
A12: 9 | B12: Porta Nuova / Isola | C12: =COUNTIF(Fichas!$A$2:$A$260,$A12) -> 10 | D12: =COUNTIFS(Fichas!$A$2:$A$260,$A12,Fichas!$L$2:$L$260,"Sim") -> 0 | E12: =C12-D12 -> 10 | F12: =IFERROR(D12/C12,0) -> 0
A13: 10 | B13: Navigli | C13: =COUNTIF(Fichas!$A$2:$A$260,$A13) -> 8 | D13: =COUNTIFS(Fichas!$A$2:$A$260,$A13,Fichas!$L$2:$L$260,"Sim") -> 0 | E13: =C13-D13 -> 8 | F13: =IFERROR(D13/C13,0) -> 0
A14: 11 | B14: CityLife / San Siro | C14: =COUNTIF(Fichas!$A$2:$A$260,$A14) -> 7 | D14: =COUNTIFS(Fichas!$A$2:$A$260,$A14,Fichas!$L$2:$L$260,"Sim") -> 0 | E14: =C14-D14 -> 7 | F14: =IFERROR(D14/C14,0) -> 0
A15: 12 | B15: Luxury concierge | C15: =COUNTIF(Fichas!$A$2:$A$260,$A15) -> 10 | D15: =COUNTIFS(Fichas!$A$2:$A$260,$A15,Fichas!$L$2:$L$260,"Sim") -> 0 | E15: =C15-D15 -> 10 | F15: =IFERROR(D15/C15,0) -> 0
... A18: 15 | B18: Experiências premium | C18: =COUNTIF(Fichas!$A$2:$A$260,$A18) -> 16 | D18: =COUNTIFS(Fichas!$A$2:$A$260,$A18,Fichas!$L$2:$L$260,"Sim") -> 0 | E18: =C18-D18 -> 16 | F18: =IFERROR(D18/C18,0) -> 0
B19: TOTAL | C19: =SUM(C4:C18) -> 163 | D19: =SUM(D4:D18) -> 0 | E19: =C19-D19 -> 163 | F19: =IFERROR(D19/C19,0) -> 0
A21: Fichas com nota preenchida | D21: =COUNTIF(Fichas!$N$2:$N$260,">0") -> 0
A22: Marcados como LGBTQIA+ friendly | D22: =COUNTIF(Fichas!$V$2:$V$260,"Sim") -> 0
A23: Marcados como acessíveis | D23: =COUNTIF(Fichas!$W$2:$W$260,"Sim") -> 0
A24: Servem com chuva | D24: =COUNTIF(Fichas!$U$2:$U$260,"Sim") -> 0
